Workbook
Name Dia_Lunes: Datos!$A$2:$A$7
Name Dia_Martes: Datos!$B$2:$B$7
Name Dia_Miercoles: Datos!$C$2:$C$7
Name Dia_Jueves: Datos!$D$2:$D$7
Name Dia_Viernes: Datos!$E$2:$E$7
Name Dias_Lookup: Datos!$A$1:$E$1

Sheet Registro
A1: REGISTRO DE ENTRENAMIENTO EN CASA
A2: Ingresa tus datos de cada sesión. Usa los botones o escribe directamente.
A4: ENTRADA RÁPIDA
A5: Fecha: | B5: Día/Rutina: | C5: Ejercicio: | D5: Series: | E5: Reps: | F5: Peso (kg): | G5: Descanso (seg): | H5: Notas:
A6: =TODAY() | I6: =IF(B6="","",IF(LEFT(B6,5)="Lunes","Dia_Lunes",IF(LEFT(B6,6)="Martes","Dia_Martes",IF(LEFT(B6,4)="Miér","Dia_Miercoles",IF(LEFT(B6,6)="Jueves","Dia_Jueves",IF(LEFT(B6,7)="Viernes","Dia_Viernes",""))))))
B8: ▶ REGISTRAR ENTRADA | E8: ✕ LIMPIAR CAMPOS | G8: ⟳ DESHACER ÚLTIMO
A10: HISTORIAL DE ENTRENAMIENTOS
A11: Fecha | B11: Día / Rutina | C11: Ejercicio | D11: Series | E11: Reps | F11: Peso (kg) | G11: Descanso (s) | H11: Notas

Sheet Datos
A1: Lunes - Pecho y Tríceps | B1: Martes - Espalda y Bíceps | C1: Miércoles - Piernas | D1: Jueves - Hombros y Core | E1: Viernes - Full Body
A2: Flexiones clásicas | B2: Remo con mancuernas | C2: Sentadillas | D2: Press militar con mancuernas | E2: Burpees
A3: Flexiones diamante | B3: Dominadas (o banda elástica) | C3: Sentadilla búlgara | D3: Elevaciones laterales | E3: Sentadilla con salto
A4: Flexiones declinadas | B4: Remo invertido (mesa) | C4: Zancadas | D4: Elevaciones frontales | E4: Flexiones
A5: Fondos en silla | B5: Curl bíceps con mancuerna | C5: Peso muerto rumano | D5: Plancha frontal (seg) | E5: Remo con mancuernas
A6: Flexiones abiertas | B6: Curl martillo | C6: Elevación de talones | D6: Plancha lateral (seg) | E6: Zancadas con salto
A7: Extensión tríceps con mancuerna | B7: Superman | C7: Puente de glúteos | D7: Crunch abdominal | E7: Mountain climbers

Sheet Rutinas
A1: RUTINAS SEMANALES - ENTRENAMIENTO EN CASA
A2: Personaliza tus rutinas aquí. Los ejercicios aparecerán en la hoja de Registro.
A4: Lunes - Pecho y Tríceps
A5: # | B5: Ejercicio | C5: Grupo Muscular | D5: Series Obj. | E5: Reps Obj. | F5: Peso Obj. (kg)
A6: 1 | B6: Flexiones clásicas
A7: 2 | B7: Flexiones diamante
A8: 3 | B8: Flexiones declinadas
A9: 4 | B9: Fondos en silla
A10: 5 | B10: Flexiones abiertas
A11: 6 | B11: Extensión tríceps con mancuerna
A13: Martes - Espalda y Bíceps
A14: # | B14: Ejercicio | C14: Grupo Muscular | D14: Series Obj. | E14: Reps Obj. | F14: Peso Obj. (kg)
A15: 1 | B15: Remo con mancuernas
A16: 2 | B16: Dominadas (o banda elástica)
A17: 3 | B17: Remo invertido (mesa)
A18: 4 | B18: Curl bíceps con mancuerna
A19: 5 | B19: Curl martillo
A20: 6 | B20: Superman
A22: Miércoles - Piernas
A23: # | B23: Ejercicio | C23: Grupo Muscular | D23: Series Obj. | E23: Reps Obj. | F23: Peso Obj. (kg)
A24: 1 | B24: Sentadillas
A25: 2 | B25: Sentadilla búlgara
A26: 3 | B26: Zancadas
A27: 4 | B27: Peso muerto rumano
A28: 5 | B28: Elevación de talones
A29: 6 | B29: Puente de glúteos
A31: Jueves - Hombros y Core
A32: # | B32: Ejercicio | C32: Grupo Muscular | D32: Series Obj. | E32: Reps Obj. | F32: Peso Obj. (kg)
A33: 1 | B33: Press militar con mancuernas
A34: 2 | B34: Elevaciones laterales
A35: 3 | B35: Elevaciones frontales
A36: 4 | B36: Plancha frontal (seg)
A37: 5 | B37: Plancha lateral (seg)
A38: 6 | B38: Crunch abdominal
A40: Viernes - Full Body
A41: # | B41: Ejercicio | C41: Grupo Muscular | D41: Series Obj. | E41: Reps Obj. | F41: Peso Obj. (kg)
A42: 1 | B42: Burpees
A43: 2 | B43: Sentadilla con salto
A44: 3 | B44: Flexiones
A45: 4 | B45: Remo con mancuernas
...

Sheet Dashboard
A1: DASHBOARD DE ENTRENAMIENTO
A2: Resumen visual de tu progreso. Los datos se actualizan automáticamente desde la hoja Registro.
A4: MÉTRICAS CLAVE
B5: Total Sesiones | D5: Último Entreno | F5: Peso Máx (kg) | H5: Prom. Reps | J5: Volumen Total
B6: =COUNTA(Registro!A12:A200) | D6: =IF(COUNTA(Registro!A12:A200)>0,MAX(Registro!A12:A200),"-") | F6: =IF(MAX(Registro!F12:F200)>0,MAX(Registro!F12:F200),"-") | H6: =IFERROR(ROUND(AVERAGE(Registro!E12:E200),1),"-") | J6: =IFERROR(SUMPRODUCT((Registro!D12:D200)*(Registro!E12:E200)),"-")
B9: VOLUMEN POR DÍA DE RUTINA
B10: Día | C10: Sesiones | D10: Series | E10: Reps | F10: Peso Prom.
B11: Lunes | C11: =COUNTIF(Registro!B$12:B$200,"Lunes - Pecho y Tríceps") | D11: =SUMIF(Registro!B$12:B$200,"Lunes - Pecho y Tríceps",Registro!D$12:D$200) | E11: =SUMIF(Registro!B$12:B$200,"Lunes - Pecho y Tríceps",Registro!E$12:E$200) | F11: =IFERROR(AVERAGEIF(Registro!B$12:B$200,"Lunes - Pecho y Tríceps",Registro!F$12:F$200),0)
B12: Martes | C12: =COUNTIF(Registro!B$12:B$200,"Martes - Espalda y Bíceps") | D12: =SUMIF(Registro!B$12:B$200,"Martes - Espalda y Bíceps",Registro!D$12:D$200) | E12: =SUMIF(Registro!B$12:B$200,"Martes - Espalda y Bíceps",Registro!E$12:E$200) | F12: =IFERROR(AVERAGEIF(Registro!B$12:B$200,"Martes - Espalda y Bíceps",Registro!F$12:F$200),0)
B13: Miércoles | C13: =COUNTIF(Registro!B$12:B$200,"Miércoles - Piernas") | D13: =SUMIF(Registro!B$12:B$200,"Miércoles - Piernas",Registro!D$12:D$200) | E13: =SUMIF(Registro!B$12:B$200,"Miércoles - Piernas",Registro!E$12:E$200) | F13: =IFERROR(AVERAGEIF(Registro!B$12:B$200,"Miércoles - Piernas",Registro!F$12:F$200),0)
B14: Jueves | C14: =COUNTIF(Registro!B$12:B$200,"Jueves - Hombros y Core") | D14: =SUMIF(Registro!B$12:B$200,"Jueves - Hombros y Core",Registro!D$12:D$200) | E14: =SUMIF(Registro!B$12:B$200,"Jueves - Hombros y Core",Registro!E$12:E$200) | F14: =IFERROR(AVERAGEIF(Registro!B$12:B$200,"Jueves - Hombros y Core",Registro!F$12:F$200),0)
B15: Viernes | C15: =COUNTIF(Registro!B$12:B$200,"Viernes - Full Body") | D15: =SUMIF(Registro!B$12:B$200,"Viernes - Full Body",Registro!D$12:D$200) | E15: =SUMIF(Registro!B$12:B$200,"Viernes - Full Body",Registro!E$12:E$200) | F15: =IFERROR(AVERAGEIF(Registro!B$12:B$200,"Viernes - Full Body",Registro!F$12:F$200),0)
B17: INSIGHTS
B18: Días sin entrenar | C18: =IF(COUNTA(Registro!A12:A200)>0,TODAY()-MAX(Registro!A12:A200),"-")
B19: Sesiones esta semana | C19: =COUNTIFS(Registro!A12:A200,">="&(TODAY()-WEEKDAY(TODAY(),2)+1),Registro!A12:A200,"<="&TODAY())
B20: Sesiones este mes | C20: =COUNTIFS(Registro!A12:A200,">="&DATE(YEAR(TODAY()),MONTH(TODAY()),1),Registro!A12:A200,"<="&TODAY())
B21: Ejercicio más frecuente | C21: =IFERROR(INDEX(Registro!C12:C200,MATCH(MAX(COUNTIF(Registro!C12:C200,Registro!C12:C200)),COUNTIF(Registro!C12:C200,Registro!C12:C200),0)),"-")
B22: Prom. series por sesión | C22: =IFERROR(ROUND(AVERAGE(Registro!D12:D200),1),"-")
B23: Mayor volumen en 1 registro | C23: =IFERROR(MAX(Registro!D12:D200*Registro!E12:E200),"-")
B26: ÚLTIMOS 10 REGISTROS
B27: Fecha | C27: Rutina | D27: Ejercicio | E27: Reps | F27: Peso (kg)
B28: =IFERROR(INDEX(Registro!A$12:A$200,COUNTA(Registro!A$12:A$200)-0),"") | C28: =IFERROR(INDEX(Registro!B$12:B$200,COUNTA(Registro!A$12:A$200)-0),"") | D28: =IFERROR(INDEX(Registro!C$12:C$200,COUNTA(Registro!A$12:A$200)-0),"") | E28: =IFERROR(INDEX(Registro!E$12:E$200,COUNTA(Registro!A$12:A$200)-0),"") | F28: =IFERROR(INDEX(Registro!F$12:F$200,COUNTA(Registro!A$12:A$200)-0),"")
B29: =IFERROR(INDEX(Registro!A$12:A$200,COUNTA(Registro!A$12:A$200)-1),"") | C29: =IFERROR(INDEX(Registro!B$12:B$200,COUNTA(Registro!A$12:A$200)-1),"") | D29: =IFERROR(INDEX(Registro!C$12:C$200,COUNTA(Registro!A$12:A$200)-1),"") | E29: =IFERROR(INDEX(Registro!E$12:E$200,COUNTA(Registro!A$12:A$200)-1),"") | F29: =IFERROR(INDEX(Registro!F$12:F$200,COUNTA(Registro!A$12:A$200)-1),"")
B30: =IFERROR(INDEX(Registro!A$12:A$200,COUNTA(Registro!A$12:A$200)-2),"") | C30: =IFERROR(INDEX(Registro!B$12:B$200,COUNTA(Registro!A$12:A$200)-2),"") | D30: =IFERROR(INDEX(Registro!C$12:C$200,COUNTA(Registro!A$12:A$200)-2),"") | E30: =IFERROR(INDEX(Registro!E$12:E$200,COUNTA(Registro!A$12:A$200)-2),"") | F30: =IFERROR(INDEX(Registro!F$12:F$200,COUNTA(Registro!A$12:A$200)-2),"")
B31: =IFERROR(INDEX(Registro!A$12:A$200,COUNTA(Registro!A$12:A$200)-3),"") | C31: =IFERROR(INDEX(Registro!B$12:B$200,COUNTA(Registro!A$12:A$200)-3),"") | D31: =IFERROR(INDEX(Registro!C$12:C$200,COUNTA(Registro!A$12:A$200)-3),"") | E31: =IFERROR(INDEX(Registro!E$12:E$200,COUNTA(Registro!A$12:A$200)-3),"") | F31: =IFERROR(INDEX(Registro!F$12:F$200,COUNTA(Registro!A$12:A$200)-3),"")
B32: =IFERROR(INDEX(Registro!A$12:A$200,COUNTA(Registro!A$12:A$200)-4),"") | C32: =IFERROR(INDEX(Registro!B$12:B$200,COUNTA(Registro!A$12:A$200)-4),"") | D32: =IFERROR(INDEX(Registro!C$12:C$200,COUNTA(Registro!A$12:A$200)-4),"") | E32: =IFERROR(INDEX(Registro!E$12:E$200,COUNTA(Registro!A$12:A$200)-4),"") | F32: =IFERROR(INDEX(Registro!F$12:F$200,COUNTA(Registro!A$12:A$200)-4),"")
B33: =IFERROR(INDEX(Registro!A$12:A$200,COUNTA(Registro!A$12:A$200)-5),"") | C33: =IFERROR(INDEX(Registro!B$12:B$200,COUNTA(Registro!A$12:A$200)-5),"") | D33: =IFERROR(INDEX(Registro!C$12:C$200,COUNTA(Registro!A$12:A$200)-5),"") | E33: =IFERROR(INDEX(Registro!E$12:E$200,COUNTA(Registro!A$12:A$200)-5),"") | F33: =IFERROR(INDEX(Registro!F$12:F$200,COUNTA(Registro!A$12:A$200)-5),"")
B34: =IFERROR(INDEX(Registro!A$12:A$200,COUNTA(Registro!A$12:A$200)-6),"") | C34: =IFERROR(INDEX(Registro!B$12:B$200,COUNTA(Registro!A$12:A$200)-6),"") | D34: =IFERROR(INDEX(Registro!C$12:C$200,COUNTA(Registro!A$12:A$200)-6),"") | E34: =IFERROR(INDEX(Registro!E$12:E$200,COUNTA(Registro!A$12:A$200)-6),"") | F34: =IFERROR(INDEX(Registro!F$12:F$200,COUNTA(Registro!A$12:A$200)-6),"")
B35: =IFERROR(INDEX(Registro!A$12:A$200,COUNTA(Registro!A$12:A$200)-7),"") | C35: =IFERROR(INDEX(Registro!B$12:B$200,COUNTA(Registro!A$12:A$200)-7),"") | D35: =IFERROR(INDEX(Registro!C$12:C$200,COUNTA(Registro!A$12:A$200)-7),"") | E35: =IFERROR(INDEX(Registro!E$12:E$200,COUNTA(Registro!A$12:A$200)-7),"") | F35: =IFERROR(INDEX(Registro!F$12:F$200,COUNTA(Registro!A$12:A$200)-7),"")
B36: =IFERROR(INDEX(Registro!A$12:A$200,COUNTA(Registro!A$12:A$200)-8),"") | C36: =IFERROR(INDEX(Registro!B$12:B$200,COUNTA(Registro!A$12:A$200)-8),"") | D36: =IFERROR(INDEX(Registro!C$12:C$200,COUNTA(Registro!A$12:A$200)-8),"") | E36: =IFERROR(INDEX(Registro!E$12:E$200,COUNTA(Registro!A$12:A$200)-8),"") | F36: =IFERROR(INDEX(Registro!F$12:F$200,COUNTA(Registro!A$12:A$200)-8),"")
B37: =IFERROR(INDEX(Registro!A$12:A$200,COUNTA(Registro!A$12:A$200)-9),"") | C37: =IFERROR(INDEX(Registro!B$12:B$200,COUNTA(Registro!A$12:A$200)-9),"") | D37: =IFERROR(INDEX(Registro!C$12:C$200,COUNTA(Registro!A$12:A$200)-9),"") | E37: =IFERROR(INDEX(Registro!E$12:E$200,COUNTA(Registro!A$12:A$200)-9),"") | F37: =IFERROR(INDEX(Registro!F$12:F$200,COUNTA(Registro!A$12:A$200)-9),"")

Sheet Instrucciones
A1: INSTRUCCIONES DE USO
A3: HOJA 'REGISTRO'
A4: • | B4: Esta es tu hoja principal. Aquí registras cada ejercicio que hagas.
A5: • | B5: 1. La FECHA se llena automáticamente con el día de hoy.
A6: • | B6: 2. Selecciona el DÍA/RUTINA del desplegable (Lunes-Pecho, Martes-Espalda, etc.).
A7: • | B7: 3. Escribe el nombre del EJERCICIO que realizaste.
A8: • | B8: 4. Ingresa el número de SERIES, REPETICIONES y PESO usado.
A9: • | B9: 5. Opcionalmente agrega el tiempo de DESCANSO y NOTAS.
A10: • | B10: 6. Haz clic en '▶ REGISTRAR ENTRADA' para mover los datos al historial.
A11: • | B11: 7. Usa '✕ LIMPIAR CAMPOS' para borrar la zona de entrada.
A12: • | B12: 8. Usa '⟳ DESHACER ÚLTIMO' para eliminar el último registro.
A14: HOJA 'RUTINAS'
A15: • | B15: Aquí están las rutinas predefinidas para 5 días de la semana.
A16: • | B16: Puedes editar los ejercicios, agregar objetivos de series/reps/peso.
A17: • | B17: Los nombres de los ejercicios te sirven de guía al llenar el Registro.
A19: HOJA 'DASHBOARD'
A20: • | B20: Dashboard visual con KPIs, gráficos e insights de tu progreso.
A21: • | B21: 5 tarjetas de métricas clave: sesiones, último entreno, peso máx, etc.
A22: • | B22: Gráfico de barras: sesiones por día de rutina.
A23: • | B23: Gráfico circular: distribución porcentual de entrenamientos.
A24: • | B24: Gráfico de línea: progresión del peso levantado por sesión.
A25: • | B25: Sección de insights: días sin entrenar, sesiones semanales/mensuales.
A26: • | B26: Los últimos 10 registros se muestran al final.
A28: TIPS
A29: • | B29: Registra CADA serie por separado para un seguimiento más detallado.
A30: • | B30: O registra el total de series/reps por ejercicio si prefieres algo rápido.
A31: • | B31: Revisa la hoja de Progreso regularmente para ver tu avance.
A32: • | B32: ¡La constancia es la clave! Intenta entrenar al menos 3-4 días por semana.
